Workbook

Sheet A
A1: HOW TO CALCULATE TAXES

Sheet Rates for Tax Calculation
A1: England, Wales, Northern Ireland - Income Tax (Applies to Employment/Self Employment Income/Property Income/Trust Income/Foreign Income)
A3: Band | B3: Taxable Income Range | C3: Rate | E3: Trigger these if Individual home address is in any of these jurisdictions, and if any of the income chosen above is picked by the user upon setup.
A4: Personal Allowance | B4: £0 – £12,570 | C4: 0
A5: Basic Rate | B5: £12,571 – £50,270 | C5: 0.2
A6: Higher Rate | B6: £50,271 – £125,140 | C6: 0.4
A7: Additional Rate | B7: Over £125,140 | C7: 0.45
A9: Note: The Personal Allowance tapers by £1 for every £2 of income over £100,000. It is fully withdrawn at £125,140.
A11: Example 1 | B11: (This is for calculation for users view on daily tax) | F11: Example 2 | G11: (This is for calculation for users view on daily tax)
A13: Employment | B13: 25000 | F13: Employment | G13: 25000
A14: Self Employment | B14: 55000 | F14: Self Employment | G14: 55000
A15: Property Income | B15: 24000 | F15: Property Income | G15: 24000
A16: Total Income | B16: =SUM(B13:B15) -> 104000 | F16: Pension | G16: =-12000*100/80 -> -15000
F17: Total Income less deductions | G17: =SUM(G13:G16) -> 89000
A18: Since income >100k | B18: =(104000-100000)/2 -> 2000 | C18: To take off
A19: Tapered personal allowance | B19: =12570-B18 -> 10570 | F19: Since income <100k full personal allowance given of £12,570
F20: Taxable income | G20: =SUM(G13:G15)-12570 -> 91430
A21: Taxable income | B21: =B16-B19 -> 93430 | F21: Tax | G21: =(50270-12571)*20% -> 7539.8
G22: =(G20-50271)*40% -> 16463.6
A23: Tax | B23: =(50270-12571)*20% -> 7539.8 | G23: =SUM(G21:G22) -> 24003.4
B24: =(B21-50271)*40% -> 17263.6 | F24: Tax deducted at source | G24: =12000+G16 -> -3000
B25: =SUM(B23:B24) -> 24803.4 | G25: =SUM(G23:G24) -> 21003.4
A27: If the users income uses up all the first band just take the upper limit less the lower limit. | F27: So the pension paid by the user, only helps in calculating the personal allowance, and it not being tapered. The only relief available tat will directly reduce your liability is the tax deducted at source.
A28: Then if the remainder then falls into the next 40% band, take the taxable income total less the lower limit > If this had fallen into the additional rate band, then we would have done the same as above.
A30: Scotland - Income Tax (Applies to Employment/Self Employment Income/Property Income/Trust Income/Foreign Income)
A32: Band | B32: Taxable Income Range | C32: Rate | E32: Trigger these if Individual home address is in SCOTLAND ONLY, and if any of the income chosen above is picked by the user upon setup.
A33: Personal Allowance | B33: £0 – £12,570 | C33: 0
A34: Starter Rate | B34: £12,571 – £14,876 | C34: 0.19
A35: Basic Rate | B35: £14,877 – £26,561 | C35: 0.2
A36: Intermediate Rate | B36: £26,562 – £43,662 | C36: 0.21
A37: Higher Rate | B37: £43,663 – £75,000 | C37: 0.42
A38: Advanced Rate | B38: £75,001 – £125,140 | C38: 0.45
A39: Top Rate | B39: Over £125,140 | C39: 0.48
A41: Same rules apply, just different bands.
A44: Dividend Income Rates - Applies to all UK
A46: These rates apply across England, Wales, Northern Ireland, and Scotland.
A47: Band | B47: Band amounts | C47: Tax Rate on Dividends
A48: Dividend Allowance (first £500) | B48: £0 - £500 | C48: 0
A49: Basic Rate | B49: £12,571 – £50,270 | C49: 0.0875
A50: Higher Rate | B50: £50,271 – £125,140 | C50: 0.3375
A51: Additional Rate | B51: Over £125,140 | C51: 0.3935
...

Sheet Student Loan
A1: STUDENT LOANS RULES
A2: 📌 Who Has to Pay? A user must repay student loans through Self Assessment if they: - Have income above the repayment threshold (Intellibooks will check if employment income is above the thresholds if this is pulled from HMRC's API) - Have an outstanding loan with the Student Loans Company (SLC) IntelliBooks should ask: “Do you have a student loan?” with options: - Plan 1 - Plan 2 - Plan 4 - Postgraduate Loan - No I dont 💰 How Repayment Works Loan Types and Thresholds (2025/26 estimates): - Plan 1: £24,990 at 9% - Plan 2: £27,295 at 9% - Plan 4 (Scotland): £31,395 at 9% - Postgraduate Loan: £21,000 at 6% Repayments apply to income above the respective thresholds. ✅ IntelliBooks Calculation Logic Example: Income = £42,000, Plan 2 Repayment = (42,000 - 27,295) × 9% = £1,569.45 Postgraduate Loan (if applicable): Repayment = (42,000 - 21,000) × 6% = £1,860 IB should calculate both and display separately. 📤 What to Submit to HMRC (API) You do not submit repayment amounts. You only submit the plan flags: - Student Loan Plan - Postgrad Loan
A14: API Example: | J14: API Name:
A16: "studentLoanAndPostgraduateLoan": { | J16: Student Loan Plan Type | N16: studentLoan.planType
A17: "studentLoan": { | J17: Student Loan Postgrad Loan flag | N17: studentLoan.postgradLoan
A18: "planType": "plan2"
A19: },
A20: "postgraduateLoan": {
A21: "repayment": true
A22: }

Sheet Steps for Calculation
A1: Personal Allowance tapering (step 2 calculation) | G1: For tax calculations (IB platform)
A2: 1) | B2: Calculate total income for the year (All income BUT Capital gains) | G2: 1) | H2: Take all Taxable Income (Capital gains/savings income/dividends are banded together separately as they have different rates)
A3: 2) | B3: If under 100k then use full £12,570 allowance | G3: 2) | H3: Check if total taxable income is over 100k (PA tapering check)
A4: 3) | B4: If Adjusted Net Income (total taxable income less pension and gift aid) over 100k then the following applies: | G4: 3) | H4: If loss, apply loss reliefs (if income is left after loss deducted, the allowances can be applied, if not then do not apply)
A5: 3.1) | B5: Adjusted Net Income (ANI) less £100k divided by 2 | G5: 4) | H5: If savings income check personal savings allowance (PSA) and Starting rate of £5k allowance (if under PA allowance)
A6: 3.2) | B6: Take that amount an deduct from PA of £12,570 | G6: 5) | H6: If dividend income apply automating allowance of £500
A7: 3.3) | B7: If total ANI >= £125,140 then PA is fully removed | G7: 6) | H7: Deduct Allowable Expenses
A8: 4) | B8: Now apply this amount as the new personal allowance and deduct from ANI | G8: 7) | H8: Add back Disallowable Expenses
G9: 8) | H9: Apply Capital Allowances (if user has agreed to this tax saving and has an asset in the pool that can be claimed)
G10: 9) | H10: Apply Trading Allowance if expenses and lower than £1,000
G11: 10) | H11: If Property income has been chosen and the allowable property expenses is less than £1,000, then apply this. Or if no expenses, then apply this.
G12: 11) | H12: If Capital gains income, apply CGT £3,000 allowance. Also apply reliefs (Business Asset rollover relief on next page)
G13: 12) | H13: Then Apply Personal allowance (Personal allowance calculation below with examples)
G14: 13) | H14: Then apply pension (if UK approved) gross up
G15: 14) | H15: Then apply gift aid calculation gross up if eligible
G16: 15) | H16: Then Apply trading income to income bands (Calculation on next page)
G17: 16) | H17: Then Apply savings income to savings income bands (Calculation on next page, IF THIS INCOME HAS BEEN CHOSEN)
G18: 17) | H18: Then Apply dividends income to dividend income bands (Calculation on next page, IF THIS INCOME HAS BEEN CHOSEN)
G19: 18) | H19: Then Apply capital gains income to percentage (Calculation on next page, IF THIS INCOME HAS BEEN CHOSEN)
G20: 19) | H20: Apply tax already deducted if also employed PAYE or CIS (Detected through HMRC API)
G21: 20) | H21: Apply NI class 2 and class 4
A22: Everything here needs to be calculated so use relevant rules - We need to do this so the user knows how much to put away per month. | G22: 21) | H22: Apply Student Loan to pay (look at student loan tab for calculation)
G23: 22) | H23: If self assessment plus NI is >1k - then POA (check Rates for tax calculation tab for how to calculate)
G25: Everything here needs to be calculated so use relevant rules - We need to do this so the user knows how much to put away per month.
G30: For tax return (HMRC)
G31: 1) | H31: Take all Taxable Income (Capital gains/savings income/dividends are banded together separately as they have different rates)
G32: 2) | H32: If loss, apply loss reliefs (if income is left after loss deducted, the allowances can be applied, if not then do not apply)
G33: 3) | H33: Send amounts for allowable expenses
G34: 4) | H34: Send amounts for disallowable expenses
G35: 5) | H35: Apply Capital Allowances (if user has agreed to this tax saving and has an asset in the pool that can be claimed)
G36: 6) | H36: Apply Trading Allowance if expenses and lower than £1,000
G37: 7) | H37: If Property income has been chosen and the allowable property expenses is less than £1,000, then apply this. Or if no expenses, then apply this.
G38: 8) | H38: If Capital gains income, apply CGT income only. Also apply reliefs if eligible
G39: 9) | H39: Then apply pension (if UK approved) gross up and send
G40: 10) | H40: Then apply gift aid calculation gross up if eligible - gross up and send
G41: 11) | H41: Apply tax already deducted if also employed PAYE or CIS (Detected through HMRC API)
G42: 12) | H42: Apply NI Calculations
G43: 13) | H43: Send HMRC Student loan plan type if eligible and specified by user upon setup
G50: This is how we would send to HMRC

Sheet Daily Tax Calculation method
A1: Daily Tax Calculation Method – IntelliBooks (Sole Trader)
A2: Purpose: give a clear, automatable method to (1) compute an up‑to‑date daily tax liability, (2) check if current cash is enough to cover upcoming tax deadlines, and (3) recommend a monthly set‑aside amount. This aligns with your Rules & Logic under SOLE TRADER and HMRC submission flow.
A3: 1) Data Inputs & Sources (auto‑collected)
A4: • Bank feeds (Open Banking): categorised cash in/out; CIS receipts; recurring patterns.
A5: • User profile: jurisdiction (Scotland vs rUK), marital status, student loan plan, CIS registration, pension/gift aid flags.
A6: • Income modules: self‑employment (turnover, allowable/disallowable, capital allowances), UK property (FHL/non‑FHL), dividends, savings, capital gains.
A7: • Losses: brought‑forward pools (via MTD losses API if available) and current‑year loss choices (same‑year/carry‑back/carry‑forward).
A8: • Adjustments: pensions (relief‑at‑source gross up), Gift Aid (gross up), trading/property allowances, rent‑a‑room, mortgage interest rules, PSA/starting rate, dividend allowance.
A9: • HMRC feeds (where available): PAYE employment income/tax deducted, CIS deducted at source, student loan flags, prior‑year liability for Payments on Account logic.
A10: • Config (per tax year): income tax bands (rUK/Scotland), dividend/savings/CGT allowances, NI Class 2/4 thresholds and rates.
A11: 2) High‑Level Algorithm (daily run)
A12: • A. Build YTD ledgers by source: self‑employment profit, property profit, dividends, savings, employment PAYE, CGT, other.
... A139: • What changed since yesterday: deltas from new transactions, category changes, gift aid/pension updates.

Sheet Daily TaxBot Cal Examples
A1: Daily Tax – rUK vs Scotland Worked Examples (IntelliBooks, Sole Trader)
A2: Two parallel, step-by-step examples using the same income profile. The only difference is the non‑savings income tax bands: rUK vs Scotland. Everything else (savings/dividends rules, PAYE credits, NI, buffer logic) is identical.
A3: Common Context & Timing
A4: Today: 1 Oct | Next deadline: 31 Jan | Days since 6 Apr: ~178 | Days to deadline: 122 | Months remaining: 5
A5: Assumptions shared by both examples: no Gift Aid or Pension relief; no student loan; no losses; no POA this year.
A6: Step 1 – YTD & Annualisation Factor (AF)
A7: YTD inputs (from Open Banking/HMRC):
A8: • Self‑employment profit YTD: £19,500 (turnover − allowable expenses − capital allowances)
A9: • PAYE salary YTD: £18,000; PAYE tax deducted YTD: £2,100
A10: • Savings interest YTD: £300 | Dividends YTD: £600
A11: AF (safe annualise): AF = 365 / 178 ≈ 2.05 (clamped ≤ 2.5)
A12: Step 2 – Project to Year‑End (per source)
... A54: Next deadline: 31 Jan

Sheet B
A1: TAXABLE INCOME TYPES AND ALLOWANCES FOR EACH

Sheet Income Type to Tax Form
A1: Income Type | B1: Sub-Income Category Type (Trigger) | C1: API Section | D1: API Field Name | E1: Allowances Trigger | F1: AI Flag: | G1: Rule for IB | H1: GL Name (Breakdown) | I1: Financial Statement | J1: Heading | K1: Notes
A2: Dividend Income | B2: N/A | C2: dividendsIncome | D2: dividendsIncome.ukDividends | E2: First £500 of dividend income is allowable. Total foreign and UK dividend and then deduct £500 allowance. - HMRC automatically applies and we calculate ourselves for estimated tax | F2: If user specifies this as their income type, and gives monthly range, the AI ML should recognise this and categorise this in the GL as "Dividend Income" | G2: Using Fuzzy Matching, check if amounts match what user specified for dividend income upon setup. If this is the users only income, then automatically assing to this GL Code. | H2: UK Dividend Income | I2: Income Statement | J2: Turnover | K2: Included for Tax
A3: Savings Income | B3: N/A | C3: savingsAndGainsIncome | D3: savingsAndGainsIncome.bankInterest | E3: Personal Savings Allowance/Savings Allowance - HMRC automatically applies and we calculate ourselves | F3: If user specifies this as their income type, and gives monthly range, the AI ML should recognise this and categorise this in the GL as "Savings Income" | G3: Since this mainly comes from financial instituitions, we use the MCC Code as a fall back if this income is specified all MCC Codes, 6000-6999. - Or use merchant name to see if this is interest from a financial instituition. We only use these two IF user has specified more than one income type that includes savings income. However, the rang specified should aid AI ML i making decision on type of income. | H3: UK Savings Income | I3: Income Statement | J3: Turnover | K3: Included for Tax
A4: Employment Income | B4: N/A | C4: employment | D4: employment.income | E4: pulled in from HMRC API | F4: pulled in from HMRC API | G4: Apply to API return, when IF HMRC give employment information. Use tax deducted as relief to recalculate estimated tax owed for the sake of user vision. | H4: N/A | I4: N/A | J4: N/A | K4: Only for Tax calculations not P+L as this is personal income not sales
A5: Self Employment Income (Trading Income) | B5: N/A | C5: selfemployment | D5: selfEmployment.income.turnover | E5: Trading Allowances/Capital Allowances/Use of Home as Office/Loss Relief/Pension Relief | F5: If user specifies this as their income type, and gives monthly range, the AI ML should recognise this and categorise this in the GL as "SE Income" - Also if Invoices are sent and managed through IB, this should be also recognised this way by matching amounts to invoices. | G5: If VAT, ensure to take NET amount only as turnover. | H5: UK Self Employment Income | I5: Income Statement | J5: Turnover | K5: Included for Tax
A6: Trust Income | B6: N/A | C6: trustAndEstates | D6: trustAndEstates.amount | E6: Tax deducted at source can be claimed. | F6: User would have specified if this income is received | G6: Ask user to upload documentation for tax deducted at source "taxpaid" | H6: UK Trust Income | I6: Income Statement | J6: Turnover | K6: Included for Tax
A7: Capital Gains Income | B7: N/A | C7: capitalGains | D7: capitalgains.totalGains | E7: Loss Relief/Annual Exempt Amount/Rollover Relief/Gift Holdover Relief | F7: User specifies this/ Or if unknown amount hits the bank, we notify user for confirmation if amount is out of range specified upon setup./Using Fuzzy Matching to see clues in description e.g "Sale of Car", "Sale of Asset". E.g if sale of car, check if money in from MCC Code belonging to Automotive dealers | G7: Ask user for this, if not already specified. | H7: UK Capital Gains Income | I7: Income Statement | J7: Turnover | K7: Included for Tax
A8: Foreign Income | B8: Dividend Income (Foreign) | C8: foreignIncome | D8: foreignIncome.foreignDividends | E8: First £500 of dividend income is allowable. Total foreign and UK dividend and then deduct £500 allowance/ FTCR | F8: If user specifies this income type and if amount falls withing specified range. (Trigger Remittance basis rules) | G8: Ask user to upload documentation for foreign tax deducted at source "taxpaid" | H8: Dividend Income (Foreign) | I8: Income Statement | J8: Turnover | K8: Included for Tax
A9: Foreign Income | B9: Savings Income (Foreign) | C9: foreignIncome | D9: foreignIncome.foreignInterest | E9: Personal Savings Allowance/Savings Allowance - Total with UK Savings income then deduct./FTCR | F9: If user specifies this income type and if amount falls withing specified range. (Trigger Remittance basis rules) | G9: Ask user to upload documentation for foreign tax deducted at source "taxpaid" | H9: Savings Income (Foreign) | I9: Income Statement | J9: Turnover | K9: Included for Tax
A10: Foreign Income | B10: Furnished Holiday Let (EEA Property) | C10: foreignIncome | D10: foreignIncome.eeaFhlProperty | E10: Capital Allowances/ Mortgage Interest/Pension Contributions/Rollover Relief/FTCR | F10: If user has specified this type of foreign income, Ask user for address of the property. Also detected on bank feeds, i.e from accomodation and hospitality websites such as AirBNB or Booking.com - Address of this property needs to be entered to see country and to ensure not main residence. (Trigger Remittance basis rules) | G10: Ask user to upload documentation for foreign tax deducted at source "taxpaid" | H10: Furnished Holiday Let (EEA Property) | I10: Income Statement | J10: Turnover | K10: Included for Tax
A11: Foreign Income | B11: Furnished Holiday Let (Outside UK and EEA) | C11: foreignIncome | D11: foreignIncome.foreignPropertyIncome | E11: FTCR | F11: If user has specified this type of foreign income, Ask user for address of the property. Also detected on bank feeds, i.e from accomodation and hospitality websites such as AirBNB or Booking.com - Address of this property needs to be entered to see country and to ensure not main residence. (Trigger Remittance basis rules) | G11: Ask user to upload documentation for foreign tax deducted at source "taxpaid" | H11: Furnished Holiday Let (Outside UK and EEA) | I11: Income Statement | J11: Turnover | K11: Included for Tax
A12: Foreign Income | B12: Residential Rental Income | C12: foreignIncome | D12: foreignIncome.foreignPropertyIncome | E12: FCTR/Full Mortgage Interest deduction/Letting Agent Fee/Insurance/Utilities paid by landlord/Property Management Fees | F12: If user specifies this income type and if amount falls withing specified range. (Trigger Remittance basis rules) | G12: Ask user to upload documentation for foreign tax deducted at source "taxpaid" | H12: Residential Rental Income (Foreign) | I12: Income Statement | J12: Turnover | K12: Included for Tax
... A19: UK Property Income | B19: Commerical Rental Income | C19: ukProperty | D19: ukProperty.ukNonFhlProperty | E19: Property Allowance/Capital Allowance/Finance Costs deduction | F19: If user specifies this income type and if amount falls withing specified range. | G19: <<<<<<<<<<<<<<<<<<<<<<<<<<<<<<<<<<<<<<<<<<<<< | H19: Commerical Rental Income (UK) | I19: Income Statement | J19: Turnover | K19: Included for Tax

Sheet Allowances 
D1: £ | G1: £
A2: Income Type | B2: Allowance | C2: API Name | D2: Amount | E2: Trigger When: | F2: Prompt: | G2: Calculation | H2: AI Flag: | I2: Will IB calculate this:
A3: Dividend Income | B3: Dividend Allowance | C3: HMRC Automatically applies this | D3: 500 | E3: When user picks dividends income as an income type upon setup. | F3: None | G3: Always apply full amount , no rules. | H3: If user picks dividend allowance, automatically apply £500 as an allowance. | I3: Yes for estimated tax amounts
A4: Savings Income | B4: Personal Savings Allowance | C4: HMRC Automatically applies this | D4: Basic Rate - £1,000/Higher Rate - £500/Advanced - 0 | E4: if total income for the year is less that 12,570 | F4: None | G4: Base allowance on main income type taxpayer rate if there is other income (ie employment income/self employment income) - If not then use savings rate income band (wherever it falls based on annual savings income) - Same for scotland | H4: If user picks savings allowance as an income type, automatically apply for internal calculations. If Main income type then apply then we see total cumulative net income and what band it falls in. But if secondary or tertiary, look at main income and where the net income type falls in what band. | I4: Yes for estimated tax amounts
B5: Savings Allowance - Starting Rate | C5: HMRC Automatically applies this | D5: 5000 | E5: When user picks savings income as an income type upon setup. | F5: If amount out of range specified, IB should ask the user what this income relates to. The IB will know supplier name, and match through fuzzy matching. | G5: Only available if total income is below the personal allowance threshold. Remove this allowance if annual cumulative total income over >17,570 | H5: If user picks savings allowance as an income type, automatically apply this UNTIL total net income is over the 12,570 threshold. | I5: Yes for estimated tax amounts
A6: Self Employment Income (Trading Income) | B6: Trading Allowances | C6: selfEmployment.tradingAllowance | D6: 1000 | E6: If self employment income is selected, then apply this automatically, until allowable expenses surpasses £1,000. Once this happens use allowable expense instead. | F6: If total allowable expenses under £1,000 for the year, then automatically apply. | G6: Deduct the 1,000 from the turnover, if rule applies. | H6: Deduct the 1,000 from the turnover, if rule applies. | I6: Yes for the API and Test. Tax calc. (If expenses for the year are under <1,000, we ask upon submission: "Do you want to claim the £1,000 trading allowance instead of entering expenses" - and tell them why and the benefit.
B7: Capital Allowances | C7: selfEmployment.capitalAllowances | D7: >=£500 | E7: If >£500 in category of service and auto parts as well as electronics and software, and home | F7: "Is this an item you will use for more than a short period?" | G7: Check CAPITAL ALLOWANCES Tab | H7: If met then apply capital allowances rules shown in the "Capital Allowances tab" | I7: Yes
B8: Use of Home as Office Allowance | C8: otherExpenses | D8: check calculation. | E8: Business address and Home Address are the same | F8: Ask user how many rooms in their property, and how many are used for business. (Total of Rent/mortgage Interest, Utilities, Internet, Council Tax, Home Insurance) | G8: No of rooms used/total rooms in house times cost. | H8: End of the first month of setup, ask the user if any home bills are paid - ONLY DO THIS IF BOTH ADDRESSES ARE THE SAME
B9: Loss Relief | C9: Check Tab | D9: Check Tab | E9: Check Tab | F9: Check Tab | G9: Check Tab | H9: Check Tab | I9: Check Tab
B10: Pension Reliefs | C10: pension.Contributions.totalPaymentsIntoRAS | D10: total amount paid in the year | E10: fuzzy matching shows amount paid into pension - Get AI ML to fuzzy match to list of registered UK pension providers. If on this list then assume relief, and if this income is chosen. | G10: total in paid to registered UK pension provider - pension paid in bank times by 100 divided by 80 always. | H10: Total contribution calculated is allowable | I10: Yes for estimated tax amounts, but total amount for pension calculated will be sent.
A11: Trust Income | B11: Tax Deducted at source | C11: taxTakenOff | D11: Amount that they receive is applied and put on the API. | E11: When user picks trust income as an income type upon setup. | F11: Ask user to upload document for tax taken off at source if possible. So we can see actual net income. | G11: Add the tax taken at source plus the amount received in the bank. | H11: Ensure that tax document or evidence of tax at source is uploaded upon detection of income. | I11: Yes for estimated tax amounts, and will be sent over to HMRC
A12: Capital Gains Income | B12: Loss Relief | C12: Check Tab | D12: Check Tab | E12: Check Tab | F12: Check Tab | G12: Check Tab | H12: Check Tab | I12: Check Tab
B13: Annual Exempt Amount | C13: capitalGains.annualExemptAmountUsed | D13: 3000 | E13: When user picks capital gains income as an income type upon setup. | F13: automatically applied | G13: deduct this from the net gains | H13: <<<<<<<<<<<<<<<<<<<<<<<<<<<,, | I13: Yes for estimated tax amounts, and will be sent over to HMRC
B14: Rollover Relief | C14: capitalGains.businessAssetRolloverRelief | D14: Unlimited - up to full gain can be deferred. | E14: Sale of a qualifying business asset and the proceeds are reinvested into another qualifying business asset within 3 years before or after. | F14: "Have you reinvested the proceeds of a business asset sale into another asset? If so what date (and this brings all the transactions on that date and they choose the transaction this relates to) " | G14: So the relief reduces the chargeable gain, and then in the future reduces the cost of the asset, which means nil effect and relief for this year until the asset is sold. | H14: If asset sold and bought are bought qualifying assets then relief can be applied. If gain> reinvested amount -> Defer up to reinvested amount, and tax difference now. -> Reduce new asset base cost by deferred portion only. | I14: Yes for estimated tax amounts, and will be sent over to HMRC (Gain amount, relief amount claimed, adjusted base cost of the new asset.)
A15: Dividend Income (Foreign Income) | B15: Dividend Allowance | C15: HMRC Automatically applies this | D15: 500 | E15: When user picks dividends income as an income type upon setup. | G15: Always apply full amount , no rules. | H15: If user picks dividend allowance, automatically apply £500 as an allowance. | I15: Yes for estimated tax amounts
B16: Foreign Credit Tax Relief | C16: foreignIncome.foreignTaxPaid | D16: Capped at UK TAX DUE | E16: User has specified Foreign dividend income upon setup. And amount hits the bank. | F16: Ask user to upload documentation on tax paid abroad if applicable | G16: When user specifies foreign tax, IB should compare UK translated foregin tax to UK tax. Always cap at UK tax due. If Foreign<UK then Tax payable. If Foreign>UK, then no extra tax payable. | H16: <<<<<<<<<<<<<<<<<<<<<<<<<<<,, | I16: Yes for estimated tax amounts, and will be sent over to HMRC (Gain amount, relief amount claimed, adjusted base cost of the new asset.)
B17: Remittance Basis Relief | C17: remittanceBasis | D17: either true or false if presence score is high | E17: Domicile Detection | F17: "Your data suggests a strong UK or foreign footprint. We recommend reviewing your domicile/residency status before claiming remittance basis" | I17: Developer to look at "Domicile risk" in background - We will create a presence score.
A18: Savings Income (Foreign Income) | B18: Personal Savings Allowance | C18: HMRC Automatically applies this | D18: Basic Rate - £1,000/Higher Rate - £500/Advanced - 0 | F18: None | G18: Base allowance on main income type taxpayer rate if there is other income (ie employment income/self employment income) - If not then use savings rate income band (wherever it falls based on annual savings income) - Same for scotland | H18: If user picks savings allowance as an income type, automatically apply for internal calculations. If Main income type then apply then we see total cumulative net income and what band it falls in. But if secondary or tertiary, look at main income and where the net income type falls in what band. | I18: Yes for estimated tax amounts
B19: Savings Allowance - Starting Rate | C19: HMRC Automatically applies this | D19: 5000 | E19: When user picks savings income as an income type upon setup. | F19: If amount out of range specified, IB should ask the user what this income relates to. The IB will know supplier name, and match through fuzzy matching. | G19: Only available if total income is below the personal allowance threshold. Remove this allowance if annual cumulative total income over >17,570 | H19: If user picks savings allowance as an income type, automatically apply this UNTIL total net income is over the 12,570 threshold. | I19: Yes for estimated tax amounts
B20: Foreign Credit Tax Relief | C20: foreignIncome.foreignTaxPaid | D20: Capped at UK TAX DUE | E20: User has specified Foreign savings income upon setup. And amount hits the bank. | F20: Ask user to upload documentation on tax paid abroad if applicable | G20: When user specifies foreign tax, IB should compare UK translated foregin tax to UK tax. Always cap at UK tax due. If Foreign<UK then Tax payable. If Foreign>UK, then no extra tax payable. | H20: <<<<<<<<<<<<<<<<<<<< | I20: Yes for estimated tax amounts, and will be sent over to HMRC (Gain amount, relief amount claimed, adjusted base cost of the new asset.)
B21: Remittance Basis Relief | C21: remittanceBasis | D21: either true or false if presence score is high | E21: Domicile Detection | F21: "Your data suggests a strong UK or foreign footprint. We recommend reviewing your domicile/residency status before claiming remittance basis" | I21: Developer to look at "Domicile risk" in background - We will create a presence score.
A22: Furnished Holiday Let (EEA Property) (Foreign Income) | B22: Capital Allowances | C22: selfEmployment.capitalAllowances | D22: >=£500 | E22: If >£500 in category of service and auto parts as well as electronics and software, and home | F22: "Is this an item you will use for more than a short period?" | G22: Check CAPITAL ALLOWANCES Tab | H22: If met then apply capital allowances rules shown in the "Capital Allowances tab" | I22: Yes
B23: Mortgage Interest | C23: financeCosts | D23: whatever is shown in GL | E23: Sub-Income category shown is picked. | F23: "You may be eligible for mortgage interest relief, since your income is an FHL, Can I have a breakdown of the mortgage interest on these payments? These are 100% deductible and will save you tax!" Then also give user as option to ask where they can get this information - "If you do not have this on your Lnder's online portal, please ask them for a copy of this document. We would also need to retain this for HMRC" | G23: Is an allowable expense, deduct 100% of cost | H23: <<<<<<<<<<<<<<<<<<<< | I23: Yes for estimated tax amounts, and will be sent over to HMRC (Gain amount, relief amount claimed, adjusted base cost of the new asset.)
B24: Pension Reliefs | C24: totalPaymentsIntoRAS | D24: total amount paid in the year | E24: fuzzy matching shows amount paid into pension - Get AI ML to fuzzy match to list of registered UK pension providers. If on this list then assume relief, and if this income is chosen. | G24: total in paid to registered UK pension provider - pension paid in bank times by 100 divided by 80 always. Then also increase tax bands by this amount | H24: Total contribution calculated is allowable | I24: Yes for estimated tax amounts, but total amount for pension calculated will be sent.
B25: Foreign Credit Tax Relief | C25: foreignIncome.foreignTaxPaid | D25: Capped at UK TAX DUE | E25: User has specified Foreign savings income upon setup. And amount hits the bank. | F25: Ask user to upload documentation on tax paid abroad if applicable | G25: When user specifies foreign tax, IB should compare UK translated foregin tax to UK tax. Always cap at UK tax due. If Foreign<UK then Tax payable. If Foreign>UK, then no extra tax payable. | H25: <<<<<<<<<<<<<<<<<<<< | I25: Yes for estimated tax amounts, and will be sent over to HMRC (Gain amount, relief amount claimed, adjusted base cost of the new asset.)
B26: Remittance Basis Relief | C26: remittanceBasis | D26: either true or false if presence score is high | E26: Domicile Detection | F26: "Your data suggests a strong UK or foreign footprint. We recommend reviewing your domicile/residency status before claiming remittance basis" | I26: Developer to look at "Domicile risk" in background - We will create a presence score.
A27: Furnished Holiday Let (Outside UK and EEA) (Foreign Income) | B27: Foreign Credit Tax Relief | C27: foreignIncome.foreignTaxPaid | D27: Capped at UK TAX DUE | E27: User has specified Foreign savings income upon setup. And amount hits the bank. | F27: Ask user to upload documentation on tax paid abroad if applicable | G27: When user specifies foreign tax, IB should compare UK translated foregin tax to UK tax. Always cap at UK tax due. If Foreign<UK then Tax payable. If Foreign>UK, then no extra tax payable. | H27: <<<<<<<<<<<<<<<<<<<< | I27: Yes for estimated tax amounts, and will be sent over to HMRC (Gain amount, relief amount claimed, adjusted base cost of the new asset.)
B28: Remittance Basis Relief | C28: remittanceBasis | D28: either true or false if presence score is high | E28: Domicile Detection | F28: "Your data suggests a strong UK or foreign footprint. We recommend reviewing your domicile/residency status before claiming remittance basis" | I28: Developer to look at "Domicile risk" in background - We will create a presence score.
A29: Residential Rental Income (Foreign Income) | B29: Foreign Credit Tax Relief | C29: foreignIncome.foreignTaxPaid | D29: Capped at UK TAX DUE | E29: User has specified Foreign property income for residential properties upon setup. And amount hits the bank. | F29: Ask user to upload documentation on tax paid abroad if applicable | G29: When user specifies foreign tax, IB should compare UK translated foregin tax to UK tax. Always cap at UK tax due. If Foreign<UK then Tax payable. If Foreign>UK, then no extra tax payable. | H29: <<<<<<<<<<<<<<<<<<<< | I29: Yes for estimated tax amounts, and will be sent over to HMRC (Gain amount, relief amount claimed, adjusted base cost of the new asset.)
B30: Partial Mortgage Interest deduction | C30: financeCosts | D30: whatever is shown in GL | E30: Sub-Income category shown is picked. | F30: "You may be eligible for mortgage interest relief, since your income is an FHL, Can I have a breakdown of the mortgage interest on these payments? These are 100% deductible and will save you tax!" Then also give user as option to ask where they can get this information - "If you do not have this on your Lnder's online portal, please ask them for a copy of this document. We would also need to retain this for HMRC" | G30: Is an allowable expense, deduct 20% of cost | H30: <<<<<<<<<<<<<<<<<<<< | I30: Yes for estimated tax amounts, and will be sent over to HMRC (Gain amount, relief amount claimed, adjusted base cost of the new asset.)
B31: Remittance Basis Relief | C31: remittanceBasis | D31: either true or false if presence score is high | E31: Domicile Detection | F31: "Your data suggests a strong UK or foreign footprint. We recommend reviewing your domicile/residency status before claiming remittance basis" | I31: Developer to look at "Domicile risk" in background - We will create a presence score.
A32: Commerical Rental Income (Foreign Income) | B32: Foreign Credit Tax Relief | C32: foreignIncome.foreignTaxPaid | D32: Capped at UK TAX DUE | E32: User has specified Foreign property income for residential properties upon setup. And amount hits the bank. | F32: Ask user to upload documentation on tax paid abroad if applicable | G32: When user specifies foreign tax, IB should compare UK translated foregin tax to UK tax. Always cap at UK tax due. If Foreign<UK then Tax payable. If Foreign>UK, then no extra tax payable. | H32: <<<<<<<<<<<<<<<<<<<< | I32: Yes for estimated tax amounts, and will be sent over to HMRC (Gain amount, relief amount claimed, adjusted base cost of the new asset.)
B33: Remittance Basis Relief | C33: foreignIncome.remittanceBasis | D33: either true or false if presence score is high | E33: Domicile Detection | F33: "Your data suggests a strong UK or foreign footprint. We recommend reviewing your domicile/residency status before claiming remittance basis" | I33: Developer to look at "Domicile risk" in background - We will create a presence score.
A34: Capital Gains (Foreign Income) | B34: Foreign Credit Tax Relief | C34: foreignIncome.foreignTaxPaid | D34: Capped at UK TAX DUE | E34: User has specified Foreign property income for residential properties upon setup. And amount hits the bank. | F34: Ask user to upload documentation on tax paid abroad if applicable | G34: When user specifies foreign tax, IB should compare UK translated foregin tax to UK tax. Always cap at UK tax due. If Foreign<UK then Tax payable. If Foreign>UK, then no extra tax payable. | H34: <<<<<<<<<<<<<<<<<<<< | I34: Yes for estimated tax amounts, and will be sent over to HMRC (Gain amount, relief amount claimed, adjusted base cost of the new asset.)
B35: Annual Exempt Amount | C35: capital.Gains.annualExemptAmountUsed | D35: 3000 | E35: When user picks capital gains income as an income type upon setup. | F35: automatically applied | G35: deduct this from the net gains | H35: <<<<<<<<<<<<<<<<<<<< | I35: Yes for estimated tax amounts, and will be sent over to HMRC
B36: Loss Relief | C36: Check Tab | D36: Check Tab | E36: Check Tab | F36: Check Tab | G36: Check Tab | H36: Check Tab | I36: Check Tab
B37: Remittance Basis Relief | C37: remittanceBasis | D37: either true or false if presence score is high | E37: Domicile Detection | F37: "Your data suggests a strong UK or foreign footprint. We recommend reviewing your domicile/residency status before claiming remittance basis" | I37: Developer to look at "Domicile risk" in background - We will create a presence score.
A38: Employment Income (Foreign Income) | B38: Foreign Credit Tax Relief | C38: foreignIncome.foreignTaxPaid | D38: Capped at UK TAX DUE | E38: User has specified Foreign property income for residential properties upon setup. And amount hits the bank. | F38: Ask user to upload documentation on tax paid abroad if applicable | G38: When user specifies foreign tax, IB should compare UK translated foregin tax to UK tax. Always cap at UK tax due. If Foreign<UK then Tax payable. If Foreign>UK, then no extra tax payable. | H38: <<<<<<<<<<<<<<<<<<<< | I38: Yes for estimated tax amounts, and will be sent over to HMRC (Gain amount, relief amount claimed, adjusted base cost of the new asset.)
B39: Remittance Basis Relief | C39: remittanceBasis | D39: either true or false if presence score is high | E39: Domicile Detection | F39: "Your data suggests a strong UK or foreign footprint. We recommend reviewing your domicile/residency status before claiming remittance basis" | I39: Developer to look at "Domicile risk" in background - We will create a presence score.
A40: UK Property Income - Furnished Holiday Let | B40: Capital Allowances | C40: selfEmployment.capitalAllowances | D40: >=£500 | E40: If >£500 in category of service and auto parts as well as electronics and software, and home | F40: "Is this an item you will use for more than a short period?" | G40: Check CAPITAL ALLOWANCES Tab | H40: If met then apply capital allowances rules shown in the "Capital Allowances tab" | I40: Yes
...

Sheet Other reliefs
A1: Relief / Scheme | B1: Tax Effect | C1: HMRC API Field | D1: API Section (Submission Context) | E1: User Prompt | F1: Trigger in IntelliBooks | G1: Notes | H1: Bank Transaction Clues | I1: IntelliBooks Categorisation | J1: API Section Mapping | K1: Claim at Individual Level?
A2: Enterprise Investment Scheme (EIS) | B2: 30% income tax relief on qualifying investments | C2: reliefs.eisRelief | D2: individual-reliefs | E2: We detected an investment. Was this an EIS qualifying investment? | F2: Ask: 'Did you invest under the Enterprise Investment Scheme?' | G2: Can carry back 1 year; capped at £1m ordinary, £2m KIC. | H2: Transaction ref contains 'EIS Share Issue', broker name | I2: Investment | J2: individual-reliefs → reliefs.eisRelief | K2: Yes
A3: Seed Enterprise Investment Scheme (SEIS) | B3: 50% relief on qualifying investments | C3: reliefs.seisRelief | D3: individual-reliefs | E3: We detected an investment. Was this a SEIS qualifying investment? | F3: Ask: 'Did you invest under the SEIS scheme?' | G3: Max £100k per year; can carry back. | H3: Transaction ref contains 'SEIS Subscription' | I3: Investment | J3: individual-reliefs → reliefs.seisRelief | K3: Yes
A4: Venture Capital Trust (VCT) | B4: 30% relief on new VCT subscriptions | C4: reliefs.vctSubscriptions | D4: individual-reliefs | E4: Was this a qualifying VCT investment? | F4: Ask: 'Did you subscribe to new shares in a Venture Capital Trust?' | G4: Up to £200k per year. | H4: Transaction ref: 'VCT Shares', broker statement | I4: Investment | J4: individual-reliefs → reliefs.vctSubscriptions | K4: Yes
A5: Community Investment Tax Relief (CITR) | B5: 5% of investment each year for 5 years | C5: reliefs.communityInvestment | D5: individual-reliefs | E5: Was this payment into a Community Investment scheme (CITR)? | F5: Ask: 'Did you invest in a Community Development Finance Institution?' | G5: Must have accredited CITR certificate. | H5: Merchant: Community Bank, CDFI Ltd | I5: Investment | J5: individual-reliefs → reliefs.communityInvestment | K5: Yes
A6: Qualifying Loan Interest | B6: Relief for interest paid on qualifying loans | C6: reliefs.loanInterest | D6: individual-reliefs | E6: You paid loan interest. Was this a qualifying investment loan? | F6: Ask: 'Did you pay interest on qualifying loans (e.g. to invest in a partnership)?' | G6: Includes loans for partnerships, co-ownership trusts, close companies. | H6: Ref: 'Loan Repayment HSBC', 'Interest Payment Barclays' | I6: Investment | J6: individual-reliefs → reliefs.loanInterest | K6: Yes
A7: Maintenance Payments Relief | B7: Relief for certain pre-1989 divorce settlements | C7: reliefs.maintenancePayments | D7: individual-reliefs | E7: Is this a legally required maintenance payment under pre-1989 rules? | F7: Ask: 'Did you make legally required maintenance payments?' | G7: Applies only if court order and recipient born pre-1935. | H7: Ref: 'Court Order Payment', 'CSA/Child Support' | I7: Investment | J7: individual-reliefs → reliefs.maintenancePayments | K7: Yes
A8: Deficiency Relief | B8: Relief for life assurance policy deficiencies | C8: reliefs.deficiencyRelief | D8: individual-reliefs | E8: Do you have deficiency relief to claim on life assurance policies? | F8: Ask: 'Do you have deficiency relief to claim on life assurance policies?' | G8: Rare; reduces taxable income on chargeable event gains. | H8: Ref: Life Assurance company payout / deficiency adjustment | I8: Investment | J8: individual-reliefs → reliefs.deficiencyRelief | K8: Yes

Sheet Capital Allowances
A1: Type of Capital Allowance | B1: API Name
A2: Capital Allowances | B2: selfEmployment.capitalAllowances
A3: Annual Investment Allowance (AIA) | B3: annualInvestmentAllowance
A4: Main Pool Allowance | B4: capitalAllowance.MainPool
A5: Special Rate Pool | B5: capitalAllowance.SpecialRatePool
A6: Single Asset Pool | B6: capitalAllowance.SingleAssetPool
A7: Zero Emissions Goods Vehicle Allowance (FYA) | B7: zeroEmissionsGoodsVehicleAllowance
A9: IB could prompt upon setup: | B9: In the last 5 years have you purchased a vehicle (over £500) at all?
B10: If "Yes" list types of vehicles, Give cost, and year purchased.
A12: General
A13: Asset Type | B13: AIA Eligible? | C13: If AIA Used Up → Pool | D13: Notes | E13: How to calculate?
A14: Car 0 CO₂ & Brand New | B14: No | C14: First Year Allowance | D14: Cars never qualify for AIA. If ≤50g/km CO₂ then FYA | E14: Full amount can be deducted from taxable profits
A15: Car 0 g/km CO₂ & Used | B15: No | C15: Main Pool (18%) | D15: Cars never qualify for AIA. | E15: Put full thing into main pool pot b/f balance - This is where 18% will be deducted per year.
A16: Car 1 g/km >= ≤ 50g/km CO₂ | B16: No | C16: Main Pool (18%) | D16: Cars never qualify for AIA. | E16: Put full cost into main pool pot b/f balance - This is where 18% will be deducted from taxable profits per year.
A17: Car >50g/km CO₂ | B17: No | C17: Special Rate Pool (6%) | D17: Cars never qualify for AIA. | E17: Put full cost into special rate pool pot b/f balance - This is where 6% will be deducted per year.
A18: Car (Partial Business use) | B18: No | C18: Main Pool | D18: Cars never qualify for AIA. | E18: If partial business use ALWAYS create own pool - take business percentage specified and multiply by 18%.
A19: Van 0 CO₂ & Brand New | B19: Yes | C19: First Year Allowance | D19: First Year Allowance (FYA) if electric. If brand new then FYA, if not then AIA. | E19: Full amount can be deducted from taxable profits
A20: Van 0 g/km CO₂ & Used | B20: Yes | C20: Main Pool (18%) | D20: Only goes to Main pool if AIA is all used up | E20: Put full thing into main pool pot b/f balance - This is where 18% will be deducted per year.
A21: Van 1 g/km >= ≤ 50g/km CO₂ | B21: Yes | C21: Main Pool (18%) | D21: Only goes to Main pool if AIA is all used up | E21: Put full thing into main pool pot b/f balance - This is where 18% will be deducted per year.
A22: Van >50g/km CO₂ | B22: Yes | C22: Special Rate Pool (6%) | D22: Only goes to Special pool if AIA is all used up | E22: Put full thing into special rate pool pot b/f balance - This is where 6% will be deducted per year.
A23: Van (Partial Business use) | B23: Yes | C23: Main Pool | D23: First Year Allowance (FYA) if electric. If brand new then FYA, if not then AIA. | E23: If partial business use ALWAYS create own pool - take business percentage specified and multiply by 18%.
A24: Motorcycle | B24: Yes | C24: Main Pool (18%) | D24: Always qualifies. | E24: Put full cost into main pool pot b/f balance - This is where 18% will be deducted from taxable profits per year.
... A46: Software (capitalised development costs) | B46: Yes | C46: Main Pool (18%) | D46: If capitalised, else revenue deduction. | E46: Put full cost into main pool pot b/f balance - This is where 18% will be deducted from taxable profits per year.
A50: Property Income (FHL)
A51: List of Assets | B51: AIA Eligible? | C51: If AIA Used Up → Pool | D51: Calculation for IB | E51: ONLY IF AIA OF £1M IS USED UP, IF THIS IS? THEN THE ALLOWABLE ASSETS GO INTO THE SPECIFIED POOLS <<<<<
A52: Beds | B52: Yes | C52: Main Pool (18%) | D52: Put full cost into main pool pot b/f balance - This is where 18% will be deducted from taxable profits per year.
A53: Wardrobes | B53: Yes | C53: Main Pool (18%) | D53: Put full cost into main pool pot b/f balance - This is where 18% will be deducted from taxable profits per year.
A54: Other Furniture | B54: Yes | C54: Main Pool (18%) | D54: Put full cost into main pool pot b/f balance - This is where 18% will be deducted from taxable profits per year.
A55: Cooker | B55: Yes | C55: Main Pool (18%) | D55: Put full cost into main pool pot b/f balance - This is where 18% will be deducted from taxable profits per year.
A56: Fridge | B56: Yes | C56: Main Pool (18%) | D56: Put full cost into main pool pot b/f balance - This is where 18% will be deducted from taxable profits per year.
A57: Dishwasher | B57: Yes | C57: Main Pool (18%) | D57: Put full cost into main pool pot b/f balance - This is where 18% will be deducted from taxable profits per year.
A58: Fire Alarm System | B58: Yes | C58: Main Pool (18%) | D58: Put full cost into main pool pot b/f balance - This is where 18% will be deducted from taxable profits per year.
A59: Broadband Routers | B59: Yes | C59: Main Pool (18%) | D59: Put full cost into main pool pot b/f balance - This is where 18% will be deducted from taxable profits per year.
A61: Property Income (Commercial Property)
A62: Asset Type (within commercial property) | B62: AIA Eligible? | C62: If AIA Used Up → Pool | D62: Notes
A63: Electrical systems (wiring, lighting circuits, sockets) | B63: Yes | C63: Special Rate Pool (6%) | D63: Integral feature. | E63: Put full cost into main pool pot b/f balance - This is where 6% will be deducted from taxable profits per year.
A64: Cold water systems (plumbing, pipes, tanks) | B64: Yes | C64: Special Rate Pool (6%) | D64: Integral feature. | E64: Put full cost into main pool pot b/f balance - This is where 6% will be deducted from taxable profits per year.
A65: Space and water heating systems (boilers, radiators, hot water) | B65: Yes | C65: Special Rate Pool (6%) | D65: Integral feature. | E65: Put full cost into main pool pot b/f balance - This is where 6% will be deducted from taxable profits per year.
A66: Air-conditioning and air cooling systems | B66: Yes | C66: Special Rate Pool (6%) | D66: Integral feature. | E66: Put full cost into main pool pot b/f balance - This is where 6% will be deducted from taxable profits per year.
A67: Lifts, escalators, moving walkways | B67: Yes | C67: Special Rate Pool (6%) | D67: Integral feature. | E67: Put full cost into main pool pot b/f balance - This is where 6% will be deducted from taxable profits per year.
...

Sheet Allow&Disa Exp by Truelayer cat
A1: TrueLayer classification category | B1: Classification Subcategory | C1: Allowable/Disallowable or Review | D1: IntelliBooks Prompt | E1: What IB must do in the background
A2: Cash | B2: Cash & ATM | C2: Review | D2: "Taking out cash? Let's find out if it was for business or just your weekend vibes." | E2: If not for trade, then disallow and add back to income. - Prompt user to add receipt for VAT or just evidence
A3: Cash | B3: Check | C3: Review | D3: "Can you help me with this?" | E3: If not for trade, then disallow and add back to income. - Prompt user to add receipt for VAT or just evidence
A4: Entertainment | B4: Arts | C4: Disallowable | E4: Add back to income
A5: Entertainment | B5: Music | C5: Review | D5: "Is this music for business…or just to keep you dancing while doing the dishes?" | E5: If not for trade, then disallow and add back to income. - Prompt user to add receipt for VAT or just evidence
A6: Entertainment | B6: Dating | C6: Disallowable | E6: Add back to income
A7: Entertainment | B7: Movies & DVDs | C7: Review | D7: "Was this purchase for trade purposes?" | E7: If not for trade, then disallow and add back to income. - Prompt user to add receipt for VAT or just evidence
A8: Entertainment | B8: Newspaper & Magazines | C8: Review | D8: "Is this magazine helping your business….or just your Sunday chill?" | E8: If not for trade, then disallow and add back to income. - Prompt user to add receipt for VAT or just evidence
A9: Entertainment | B9: Social Club | C9: Disallowable | E9: Add back to income
A10: Entertainment | B10: Sport | C10: Disallowable | E10: Add back to income
A11: Entertainment | B11: Games | C11: Disallowable | E11: Add back to income
A12: Education | B12: Tuition | C12: Review | D12: "Is this tuition of training related to your business or trade?" | E12: If not for trade, then disallow and add back to income. - Prompt user to add receipt for VAT or just evidence
A13: Education | B13: Student Loan | C13: Review | D13: "Is this tuition of training related to your business or trade?" | E13: If not for trade, then disallow and add back to income. - Prompt user to add receipt for VAT or just evidence
A14: Education | B14: Books & Supplies | C14: Allowable | D14: "Are these books for trade?...or just for free time?" | E14: If not for trade, then disallow and add back to income. - Prompt user to add receipt for VAT or just evidence
A15: Shopping | B15: Pets | C15: Disallowable | E15: Add back to income
A16: Shopping | B16: Groceries | C16: Review | D16: "We see you've bought some groceries! Was this grocery haul fuel for your business….or just dinner?" | E16: If not for trade, then disallow and add back to income. - Prompt user to add receipt for VAT or just evidence
A17: Shopping | B17: General | C17: Review | D17: "Oh! Im not sure what this may be. Help me with this and I sure won't forget the next time" (Then give listing of what is shown in this list, and then ask if this is for trade.) | E17: If not for trade, then disallow and add back to income. - Prompt user to add receipt for VAT or just evidence
A18: Shopping | B18: Clothing | C18: Review | D18: "Is this something your business needs….or just a nice fit?" | E18: If not for trade, then disallow and add back to income. - Prompt user to add receipt for VAT or just evidence
A19: Shopping | B19: Home | C19: Review | D19: "Was this purchase for trade purposes?" | E19: If not for trade, then disallow and add back to income. - Prompt user to add receipt for VAT or just evidence
A20: Shopping | B20: Books | C20: Review | D20: "Was this purchase for trade purposes?" | E20: If not for trade, then disallow and add back to income. - Prompt user to add receipt for VAT or just evidence
A21: Shopping | B21: Electronics & Software | C21: Allowable if under £500 | E21: Deduct from expenses if under £500
A22: Shopping | B22: Electronics & Software | C22: Review (If over >500) | D22: "This looks like an asset purchase, please help me with what this is for correct tax treatment" | E22: If not for trade, then disallow and add back to income. - Prompt user to add receipt for VAT or just evidence - If for devices then Capital allowances. If software used for trade > allowable expense if >£500 then this should trigger capital allowance questions
A23: Shopping | B23: Hobbies | C23: Disallowable | E23: Add back to income
A24: Shopping | B24: Sporting Goods | C24: Disallowable | E24: Add back to income
A25: Personal Care | B25: Hair | C25: Disallowable | E25: Add back to income
A26: Personal Care | B26: Laundry | C26: Review | D26: "Was this purchase for trade purposes?" | E26: If not for trade, then disallow and add back to income. - Prompt user to add receipt for VAT or just evidence
A27: Personal Care | B27: Beauty | C27: Disallowable | E27: Add back to income
A28: Personal Care | B28: Spa & Massage | C28: Disallowable | E28: Add back to income
A29: Health & Fitness | B29: Dentist | C29: Review | D29: "Was this purchase for trade purposes?" | E29: Add back to income
A30: Health & Fitness | B30: Doctor | C30: Allowable | E30: Deduct from expenses
A31: Health & Fitness | B31: Eye care | C31: Review | D31: "Was this purchase for trade purposes?" | E31: Add back to income
A32: Health & Fitness | B32: Pharmacy | C32: Allowable | E32: Deduct from expenses
A33: Health & Fitness | B33: Gym | C33: Disallowable | E33: Add back to income
A34: Health & Fitness | B34: Pets | C34: Disallowable | E34: Add back to income
A35: Health & Fitness | B35: Sports | C35: Disallowable | E35: Add back to income
A36: Food & Dining | B36: Catering | C36: Review | D36: "Was this purchase for trade purposes?" | E36: If not for trade, then disallow and add back to income. - Prompt user to add receipt for VAT or just evidence
A37: Food & Dining | B37: Coffee shops | C37: Review | D37: "Was this purchase for trade purposes?" | E37: Add back to income
A38: Food & Dining | B38: Delivery | C38: Review | D38: "Was this purchase for trade purposes?" | E38: If not for trade, then disallow and add back to income. - Prompt user to add receipt for VAT or just evidence
A39: Food & Dining | B39: Fast Food | C39: Review | D39: "Was this purchase for trade purposes?" | E39: Add back to income
A40: Food & Dining | B40: Restaurants | C40: Review | D40: "Was this purchase for trade purposes?" | E40: If not for trade, then disallow and add back to income. - Prompt user to add receipt for VAT or just evidence
...

Sheet Allow&Disa Exp by Merchant
A1: MERCHANT LISTING | H1: In case our subcategories do not work, the merchant listing will help us identify where they should go for tax and for accounting purposes - This is the fallback in case the first way of categorising fails.
A2: Group | B2: Name | C2: Category | D2: Allowable/Dissallowable | E2: IntelliBooks Prompt | F2: What IB must do in the background
A3: Car Brands (Automotive should b | B3: Abarth | C3: Service & Auto Parts | D3: =_xlfn.XLOOKUP(C3,'Allow&Disa Exp by Truelayer cat'!$B:$B,'Allow&Disa Exp by Truelayer cat'!$C:$C) -> Review if over >1,000 | E3: =_xlfn.XLOOKUP(C3,'Allow&Disa Exp by Truelayer cat'!$B:$B,'Allow&Disa Exp by Truelayer cat'!$D:$D) -> "Could this be a vehicle purchase?" - If user says no - "Was this purchase for trade purposes?" | F3: =_xlfn.XLOOKUP(C3,'Allow&Disa Exp by Truelayer cat'!$B:$B,'Allow&Disa Exp by Truelayer cat'!$E:$E) -> If Yes to vehicle purchase, then proceed Capital allowancesquestions (in capital allowance page) if yes for trade, deduct from expenses | H3: To make this work we have to use FUZZY MATCHING - This will help with ensuring the transaction is matched regardless of the string form.
A4: Car Brands (Automotive should b | B4: Alfa Romeo | C4: Service & Auto Parts | D4: =_xlfn.XLOOKUP(C4,'Allow&Disa Exp by Truelayer cat'!$B:$B,'Allow&Disa Exp by Truelayer cat'!$C:$C) -> Review if over >1,000 | E4: =_xlfn.XLOOKUP(C4,'Allow&Disa Exp by Truelayer cat'!$B:$B,'Allow&Disa Exp by Truelayer cat'!$D:$D) -> "Could this be a vehicle purchase?" - If user says no - "Was this purchase for trade purposes?" | F4: =_xlfn.XLOOKUP(C4,'Allow&Disa Exp by Truelayer cat'!$B:$B,'Allow&Disa Exp by Truelayer cat'!$E:$E) -> If Yes to vehicle purchase, then proceed Capital allowancesquestions (in capital allowance page) if yes for trade, deduct from expenses | H4: ✅ What is Fuzzy Matching?
A5: Car Brands (Automotive should b | B5: Alpine | C5: Service & Auto Parts | D5: =_xlfn.XLOOKUP(C5,'Allow&Disa Exp by Truelayer cat'!$B:$B,'Allow&Disa Exp by Truelayer cat'!$C:$C) -> Review if over >1,000 | E5: =_xlfn.XLOOKUP(C5,'Allow&Disa Exp by Truelayer cat'!$B:$B,'Allow&Disa Exp by Truelayer cat'!$D:$D) -> "Could this be a vehicle purchase?" - If user says no - "Was this purchase for trade purposes?" | F5: =_xlfn.XLOOKUP(C5,'Allow&Disa Exp by Truelayer cat'!$B:$B,'Allow&Disa Exp by Truelayer cat'!$E:$E) -> If Yes to vehicle purchase, then proceed Capital allowancesquestions (in capital allowance page) if yes for trade, deduct from expenses
A6: Car Brands (Automotive should b | B6: Aston Martin | C6: Service & Auto Parts | D6: =_xlfn.XLOOKUP(C6,'Allow&Disa Exp by Truelayer cat'!$B:$B,'Allow&Disa Exp by Truelayer cat'!$C:$C) -> Review if over >1,000 | E6: =_xlfn.XLOOKUP(C6,'Allow&Disa Exp by Truelayer cat'!$B:$B,'Allow&Disa Exp by Truelayer cat'!$D:$D) -> "Could this be a vehicle purchase?" - If user says no - "Was this purchase for trade purposes?" | F6: =_xlfn.XLOOKUP(C6,'Allow&Disa Exp by Truelayer cat'!$B:$B,'Allow&Disa Exp by Truelayer cat'!$E:$E) -> If Yes to vehicle purchase, then proceed Capital allowancesquestions (in capital allowance page) if yes for trade, deduct from expenses | H6: Fuzzy matching is the process of identifying approximate rather than exact matches between strings. This is crucial for:
A7: Car Brands (Automotive should b | B7: Audi | C7: Service & Auto Parts | D7: =_xlfn.XLOOKUP(C7,'Allow&Disa Exp by Truelayer cat'!$B:$B,'Allow&Disa Exp by Truelayer cat'!$C:$C) -> Review if over >1,000 | E7: =_xlfn.XLOOKUP(C7,'Allow&Disa Exp by Truelayer cat'!$B:$B,'Allow&Disa Exp by Truelayer cat'!$D:$D) -> "Could this be a vehicle purchase?" - If user says no - "Was this purchase for trade purposes?" | F7: =_xlfn.XLOOKUP(C7,'Allow&Disa Exp by Truelayer cat'!$B:$B,'Allow&Disa Exp by Truelayer cat'!$E:$E) -> If Yes to vehicle purchase, then proceed Capital allowancesquestions (in capital allowance page) if yes for trade, deduct from expenses
